2024-08-09 00:38:45,552 INFO    StreamThr :16053 [internal.py:wandb_internal():86] W&B internal server running at pid: 16053, started at: 2024-08-09 00:38:45.551343
2024-08-09 00:38:45,553 DEBUG   HandlerThread:16053 [handler.py:handle_request():146] handle_request: status
2024-08-09 00:38:45,565 INFO    WriterThread:16053 [datastore.py:open_for_write():87] open: /root/autodl-tmp/GREAD/src/wandb/run-20240809_003845-kvg7qk8e/run-kvg7qk8e.wandb
2024-08-09 00:38:45,566 DEBUG   SenderThread:16053 [sender.py:send():382] send: header
2024-08-09 00:38:45,568 DEBUG   SenderThread:16053 [sender.py:send():382] send: run
2024-08-09 00:38:46,954 ERROR   SenderThread:16053 [internal_api.py:execute():373] 403 response executing GraphQL.
2024-08-09 00:38:46,954 ERROR   SenderThread:16053 [internal_api.py:execute():374] {"errors":[{"message":"permission denied","path":["upsertBucket"],"extensions":{"code":"PERMISSION_ERROR"}}],"data":{"upsertBucket":null}}
2024-08-09 00:38:46,954 ERROR   SenderThread:16053 [sender.py:send_run():987] It appears that you do not have permission to access the requested resource. Please reach out to the project owner to grant you access. If you have the correct permissions, verify that there are no issues with your networking setup.(Error 403: Forbidden)
Traceback (most recent call last):
  File "/root/miniconda3/lib/python3.8/site-packages/wandb/sdk/lib/retry.py", line 131, in __call__
    result = self._call_fn(*args, **kwargs)
  File "/root/miniconda3/lib/python3.8/site-packages/wandb/sdk/internal/internal_api.py", line 369, in execute
    return self.client.execute(*args, **kwargs)  # type: ignore
  File "/root/miniconda3/lib/python3.8/site-packages/wandb/vendor/gql-0.2.0/wandb_gql/client.py", line 52, in execute
    result = self._get_result(document, *args, **kwargs)
  File "/root/miniconda3/lib/python3.8/site-packages/wandb/vendor/gql-0.2.0/wandb_gql/client.py", line 60, in _get_result
    return self.transport.execute(document, *args, **kwargs)
  File "/root/miniconda3/lib/python3.8/site-packages/wandb/sdk/lib/gql_request.py", line 59, in execute
    request.raise_for_status()
  File "/root/miniconda3/lib/python3.8/site-packages/requests/models.py", line 943, in raise_for_status
    raise HTTPError(http_error_msg, response=self)
requests.exceptions.HTTPError: 403 Client Error: Forbidden for url: https://api.wandb.ai/graphql

During handling of the above exception, another exception occurred:

Traceback (most recent call last):
  File "/root/miniconda3/lib/python3.8/site-packages/wandb/sdk/internal/sender.py", line 985, in send_run
    self._init_run(run, config_value_dict)
  File "/root/miniconda3/lib/python3.8/site-packages/wandb/sdk/internal/sender.py", line 1027, in _init_run
    server_run, inserted, server_messages = self._api.upsert_run(
  File "/root/miniconda3/lib/python3.8/site-packages/wandb/apis/normalize.py", line 73, in wrapper
    raise err
  File "/root/miniconda3/lib/python3.8/site-packages/wandb/apis/normalize.py", line 41, in wrapper
    return func(*args, **kwargs)
  File "/root/miniconda3/lib/python3.8/site-packages/wandb/sdk/internal/internal_api.py", line 2216, in upsert_run
    response = self.gql(
  File "/root/miniconda3/lib/python3.8/site-packages/wandb/sdk/internal/internal_api.py", line 341, in gql
    ret = self._retry_gql(
  File "/root/miniconda3/lib/python3.8/site-packages/wandb/sdk/lib/retry.py", line 147, in __call__
    retry_timedelta_triggered = check_retry_fn(e)
  File "/root/miniconda3/lib/python3.8/site-packages/wandb/util.py", line 965, in check_retry_fn
    return fallback_retry_fn(e)
  File "/root/miniconda3/lib/python3.8/site-packages/wandb/util.py", line 907, in no_retry_auth
    raise CommError(
wandb.errors.CommError: It appears that you do not have permission to access the requested resource. Please reach out to the project owner to grant you access. If you have the correct permissions, verify that there are no issues with your networking setup.(Error 403: Forbidden)
2024-08-09 00:38:48,966 DEBUG   HandlerThread:16053 [handler.py:handle_request():146] handle_request: shutdown
2024-08-09 00:38:48,967 INFO    HandlerThread:16053 [handler.py:finish():869] shutting down handler
2024-08-09 00:38:49,568 INFO    WriterThread:16053 [datastore.py:close():296] close: /root/autodl-tmp/GREAD/src/wandb/run-20240809_003845-kvg7qk8e/run-kvg7qk8e.wandb
2024-08-09 00:38:49,958 INFO    SenderThread:16053 [sender.py:finish():1572] shutting down sender
